2022-06-24 05:24:25,718 INFO    MainThread:48227 [backend.py:ensure_launched():222] started backend process with pid: 0
2022-06-24 05:24:25,719 INFO    BackendThr:48227 [internal.py:wandb_internal():90] W&B internal server running at pid: 48227, started at: 2022-06-24 05:24:25.718068
2022-06-24 05:24:25,722 INFO    MainThread:48227 [wandb_init.py:init():525] backend started and connected
2022-06-24 05:24:25,723 DEBUG   MainThread:48227 [config_util.py:dict_from_config_file():100] no default config file found in config-defaults.yaml
2022-06-24 05:24:25,727 INFO    MainThread:48227 [wandb_init.py:init():596] updated telemetry
2022-06-24 05:24:25,729 DEBUG   SenderThread:48227 [sender.py:send():235] send: header
2022-06-24 05:24:25,729 INFO    WriterThread:48227 [datastore.py:open_for_write():75] open: /Users/polcom/Code/RL/a3c_pong/wandb/run-20220624_052425-1iadzt31/run-1iadzt31.wandb
2022-06-24 05:24:25,763 INFO    MainThread:48227 [wandb_init.py:init():627] communicating run to backend with 30 second timeout
2022-06-24 05:24:25,766 DEBUG   SenderThread:48227 [sender.py:send():235] send: run
2022-06-24 05:24:25,961 ERROR   SenderThread:48227 [internal_api.py:execute():143] 401 response executing GraphQL.
2022-06-24 05:24:25,961 ERROR   SenderThread:48227 [internal_api.py:execute():144] {"errors":[{"message":"user is not logged in","path":["upsertBucket"],"extensions":{"code":"PERMISSION_ERROR"}}],"data":{"upsertBucket":null}}
2022-06-24 05:24:26,767 INFO    HandlerThread:48227 [handler.py:finish():806] shutting down handler
2022-06-24 05:24:26,768 INFO    WriterThread:48227 [datastore.py:close():279] close: /Users/polcom/Code/RL/a3c_pong/wandb/run-20220624_052425-1iadzt31/run-1iadzt31.wandb
2022-06-24 05:24:26,768 ERROR   BackendThr:48227 [internal.py:wandb_internal():165] Thread SenderThread:
Traceback (most recent call last):
  File "/Users/polcom/opt/anaconda3/envs/pytorch/lib/python3.8/site-packages/wandb/sdk/lib/retry.py", line 102, in __call__
    result = self._call_fn(*args, **kwargs)
  File "/Users/polcom/opt/anaconda3/envs/pytorch/lib/python3.8/site-packages/wandb/sdk/internal/internal_api.py", line 140, in execute
    return self.client.execute(*args, **kwargs)
  File "/Users/polcom/opt/anaconda3/envs/pytorch/lib/python3.8/site-packages/wandb/vendor/gql-0.2.0/wandb_gql/client.py", line 52, in execute
    result = self._get_result(document, *args, **kwargs)
  File "/Users/polcom/opt/anaconda3/envs/pytorch/lib/python3.8/site-packages/wandb/vendor/gql-0.2.0/wandb_gql/client.py", line 60, in _get_result
    return self.transport.execute(document, *args, **kwargs)
  File "/Users/polcom/opt/anaconda3/envs/pytorch/lib/python3.8/site-packages/wandb/vendor/gql-0.2.0/wandb_gql/transport/requests.py", line 39, in execute
    request.raise_for_status()
  File "/Users/polcom/opt/anaconda3/envs/pytorch/lib/python3.8/site-packages/requests/models.py", line 960, in raise_for_status
    raise HTTPError(http_error_msg, response=self)
requests.exceptions.HTTPError: 401 Client Error: Unauthorized for url: https://api.wandb.ai/graphql

During handling of the above exception, another exception occurred:

Traceback (most recent call last):
  File "/Users/polcom/opt/anaconda3/envs/pytorch/lib/python3.8/site-packages/wandb/apis/normalize.py", line 22, in wrapper
    return func(*args, **kwargs)
  File "/Users/polcom/opt/anaconda3/envs/pytorch/lib/python3.8/site-packages/wandb/sdk/internal/internal_api.py", line 1319, in upsert_run
    response = self.gql(mutation, variable_values=variable_values, **kwargs)
  File "/Users/polcom/opt/anaconda3/envs/pytorch/lib/python3.8/site-packages/wandb/sdk/lib/retry.py", line 118, in __call__
    if not check_retry_fn(e):
  File "/Users/polcom/opt/anaconda3/envs/pytorch/lib/python3.8/site-packages/wandb/util.py", line 883, in no_retry_auth
    raise CommError("Invalid or missing api_key. Run `wandb login`")
wandb.errors.CommError: Invalid or missing api_key. Run `wandb login`

During handling of the above exception, another exception occurred:

Traceback (most recent call last):
  File "/Users/polcom/opt/anaconda3/envs/pytorch/lib/python3.8/site-packages/wandb/sdk/internal/internal_util.py", line 51, in run
    self._run()
  File "/Users/polcom/opt/anaconda3/envs/pytorch/lib/python3.8/site-packages/wandb/sdk/internal/internal_util.py", line 102, in _run
    self._process(record)
  File "/Users/polcom/opt/anaconda3/envs/pytorch/lib/python3.8/site-packages/wandb/sdk/internal/internal.py", line 310, in _process
    self._sm.send(record)
  File "/Users/polcom/opt/anaconda3/envs/pytorch/lib/python3.8/site-packages/wandb/sdk/internal/sender.py", line 237, in send
    send_handler(record)
  File "/Users/polcom/opt/anaconda3/envs/pytorch/lib/python3.8/site-packages/wandb/sdk/internal/sender.py", line 695, in send_run
    self._init_run(run, config_value_dict)
  File "/Users/polcom/opt/anaconda3/envs/pytorch/lib/python3.8/site-packages/wandb/sdk/internal/sender.py", line 719, in _init_run
    server_run, inserted = self._api.upsert_run(
  File "/Users/polcom/opt/anaconda3/envs/pytorch/lib/python3.8/site-packages/wandb/apis/normalize.py", line 58, in wrapper
    raise CommError(message, err).with_traceback(sys.exc_info()[2])
  File "/Users/polcom/opt/anaconda3/envs/pytorch/lib/python3.8/site-packages/wandb/apis/normalize.py", line 22, in wrapper
    return func(*args, **kwargs)
  File "/Users/polcom/opt/anaconda3/envs/pytorch/lib/python3.8/site-packages/wandb/sdk/internal/internal_api.py", line 1319, in upsert_run
    response = self.gql(mutation, variable_values=variable_values, **kwargs)
  File "/Users/polcom/opt/anaconda3/envs/pytorch/lib/python3.8/site-packages/wandb/sdk/lib/retry.py", line 118, in __call__
    if not check_retry_fn(e):
  File "/Users/polcom/opt/anaconda3/envs/pytorch/lib/python3.8/site-packages/wandb/util.py", line 883, in no_retry_auth
    raise CommError("Invalid or missing api_key. Run `wandb login`")
wandb.errors.CommError: Invalid or missing api_key. Run `wandb login`
2022-06-24 05:24:55,770 INFO    MainThread:48227 [interface_shared.py:_communicate_run():326] couldn't get run from backend
2022-06-24 05:24:55,771 ERROR   MainThread:48227 [wandb_init.py:init():636] backend process timed out
2022-06-24 05:24:55,771 ERROR   MainThread:48227 [wandb_init.py:init():647] encountered error: Error communicating with wandb process
try: wandb.init(settings=wandb.Settings(start_method='fork'))
or:  wandb.init(settings=wandb.Settings(start_method='thread'))
For more info see: https://docs.wandb.ai/library/init#init-start-error
2022-06-24 05:24:55,784 ERROR   MainThread:48227 [wandb_init.py:init():1026] error
Traceback (most recent call last):
  File "/Users/polcom/opt/anaconda3/envs/pytorch/lib/python3.8/site-packages/wandb/sdk/wandb_init.py", line 999, in init
    run = wi.init()
  File "/Users/polcom/opt/anaconda3/envs/pytorch/lib/python3.8/site-packages/wandb/sdk/wandb_init.py", line 651, in init
    backend.cleanup()
  File "/Users/polcom/opt/anaconda3/envs/pytorch/lib/python3.8/site-packages/wandb/sdk/backend/backend.py", line 246, in cleanup
    self.interface.join()
  File "/Users/polcom/opt/anaconda3/envs/pytorch/lib/python3.8/site-packages/wandb/sdk/interface/interface_shared.py", line 475, in join
    super().join()
  File "/Users/polcom/opt/anaconda3/envs/pytorch/lib/python3.8/site-packages/wandb/sdk/interface/interface.py", line 666, in join
    _ = self._communicate_shutdown()
  File "/Users/polcom/opt/anaconda3/envs/pytorch/lib/python3.8/site-packages/wandb/sdk/interface/interface_shared.py", line 472, in _communicate_shutdown
    _ = self._communicate(record)
  File "/Users/polcom/opt/anaconda3/envs/pytorch/lib/python3.8/site-packages/wandb/sdk/interface/interface_shared.py", line 226, in _communicate
    return self._communicate_async(rec, local=local).get(timeout=timeout)
  File "/Users/polcom/opt/anaconda3/envs/pytorch/lib/python3.8/site-packages/wandb/sdk/interface/interface_shared.py", line 231, in _communicate_async
    raise Exception("The wandb backend process has shutdown")
Exception: The wandb backend process has shutdown
2022-06-24 05:24:56,534 INFO    MainThread:48227 [internal.py:handle_exit():80] Internal process exited
